<?xml version="1.0" ?>
<!-- =================================================================================== -->
<!-- |    This document was autogenerated by xacro from arm.urdf.xacro                 | -->
<!-- |    EDITING THIS FILE BY HAND IS NOT RECOMMENDED                                 | -->
<!-- =================================================================================== -->
<robot name="arm">
  <material name="silver">
    <color rgba="0.700 0.700 0.700 1.000"/>
  </material>
  <link name="world"/>
  <!-- arm links -->
  <link name="base_link">
    <visual>
      <origin rpy="0 0 0" xyz="0 0 0.0306835"/>
      <geometry>
        <cylinder length="0.061367" radius="0.0775"/>
      </geometry>
      <material name="silver"/>
    </visual>
    <collision>
      <origin rpy="0 0 0" xyz="0 0 0.0306835"/>
      <geometry>
        <cylinder length="0.061367" radius="0.0775"/>
      </geometry>
    </collision>
  </link>
  <joint name="world_fixed" type="fixed">
    <parent link="world"/>
    <child link="base_link"/>
  </joint>
  <link name="link_0">
    <visual>
      <origin rpy="0 0 0" xyz="0 0 0.0025"/>
      <geometry>
        <cylinder length="0.005" radius="0.0775"/>
      </geometry>
      <material name="silver"/>
    </visual>
    <collision>
      <origin rpy="0 0 0" xyz="0 0 0.0025"/>
      <geometry>
        <cylinder length="0.005" radius="0.0775"/>
      </geometry>
    </collision>
  </link>
  <link name="link_1">
    <visual>
      <origin rpy="0 0 0" xyz="0 0 0"/>
      <geometry>
        <mesh filename="package://arm_description/meshes/link_1.stl" scale="0.01 0.01 0.01"/>
      </geometry>
      <material name="silver"/>
    </visual>
    <collision>
      <origin rpy="0 0 0" xyz="0 0 0"/>
      <geometry>
        <mesh filename="package://arm_description/meshes/link_1.stl" scale="0.01 0.01 0.01"/>
      </geometry>
    </collision>
  </link>
  <link name="link_2">
    <visual>
      <origin rpy="0 0 0" xyz="0 0 0"/>
      <geometry>
        <mesh filename="package://arm_description/meshes/link_2.stl" scale="0.01 0.01 0.01"/>
      </geometry>
      <material name="silver"/>
    </visual>
    <collision>
      <origin rpy="0 0 0" xyz="0 0 0"/>
      <geometry>
        <mesh filename="package://arm_description/meshes/link_2.stl" scale="0.01 0.01 0.01"/>
      </geometry>
    </collision>
  </link>
  <link name="link_3">
    <visual>
      <geometry>
        <mesh filename="package://arm_description/meshes/link_3.stl" scale="0.01 0.01 0.01"/>
      </geometry>
      <material name="silver"/>
    </visual>
    <collision>
      <geometry>
        <mesh filename="package://arm_description/meshes/link_3.stl" scale="0.01 0.01 0.01"/>
      </geometry>
    </collision>
  </link>
  <link name="link_4">
    <visual>
      <geometry>
        <mesh filename="package://arm_description/meshes/link_4.stl" scale="0.01 0.01 0.01"/>
      </geometry>
      <material name="silver"/>
    </visual>
    <collision>
      <geometry>
        <mesh filename="package://arm_description/meshes/link_4.stl" scale="0.01 0.01 0.01"/>
      </geometry>
    </collision>
  </link>
  <link name="link_5">
    <visual>
      <geometry>
        <mesh filename="package://arm_description/meshes/link_5.stl" scale="0.01 0.01 0.01"/>
      </geometry>
      <material name="silver"/>
    </visual>
    <collision>
      <geometry>
        <mesh filename="package://arm_description/meshes/link_5.stl" scale="0.01 0.01 0.01"/>
      </geometry>
    </collision>
  </link>
  <link name="eef"/>
  <!-- revolute joints -->
  <joint name="joint_1" type="continuous">
    <origin rpy="0 0 0" xyz="0 0 0.0865"/>
    <parent link="base_link"/>
    <child link="link_0"/>
    <axis xyz="0.0 0.0 1.0"/>
    <limit effort="1" lower="-1.57" upper="1.57" velocity="0.5"/>
  </joint>
  <joint name="fix_link0_link1" type="fixed">
    <parent link="link_0"/>
    <child link="link_1"/>
  </joint>
  <joint name="joint_2" type="continuous">
    <origin rpy="0 0 0" xyz="0 0 0.045"/>
    <parent link="link_0"/>
    <child link="link_2"/>
    <axis xyz="0.0 1.0 0.0"/>
    <limit effort="1" lower="-1.57" upper="1.57" velocity="0.5"/>
  </joint>
  <joint name="joint_3" type="continuous">
    <origin rpy="0 0 0" xyz="0 0 0.112"/>
    <parent link="link_2"/>
    <child link="link_3"/>
    <axis xyz="0.0 1.0 0.0"/>
    <limit effort="1" lower="-1.57" upper="1.57" velocity="0.5"/>
  </joint>
  <joint name="joint_4" type="continuous">
    <origin rpy="0 0 0" xyz="0 0 0.110"/>
    <parent link="link_3"/>
    <child link="link_4"/>
    <axis xyz="0.0 1.0 0.0"/>
    <limit effort="1" lower="-1.57" upper="1.57" velocity="0.5"/>
  </joint>
  <joint name="joint_5" type="continuous">
    <origin rpy="0 0 0" xyz="0 0 0.068"/>
    <parent link="link_4"/>
    <child link="link_5"/>
    <axis xyz="0.0 0.0 1.0"/>
    <limit effort="1" lower="-1.57" upper="1.57" velocity="0.5"/>
  </joint>
  <joint name="eef" type="fixed">
    <origin rpy="0 0 0" xyz="0 0 0.128"/>
    <parent link="link_5"/>
    <child link="eef"/>
    <axis xyz="0.0 0.0 1.0"/>
  </joint>
</robot>

